<?xml version="1.0"?>
  <robot name="Robot1">
    <link name="base_link">
      <visual>
        <geometry>
          <box size="0.3 .3 .15"/>
        </geometry>
        <origin rpy="0 0 0" xyz="0 0 0.05"/>
        <material name="gray">
          <color rgba="0.5 0.5 0.5 1"/>
        </material>
      </visual>
    </link>

    <link name="wheel_1">
      <visual>
        <geometry>
          <cylinder length="0.05" radius="0.05"/>
        </geometry>
        <origin rpy="0 1.5 0" xyz="0.1 0.1 0"/>
          <material name="black">
            <color rgba="0 0 0 1"/>
          </material>
      </visual>
    </link>

    <link name="wheel_2">
      <visual>
        <geometry>
          <cylinder length="0.05" radius="0.05"/>
        </geometry>
        <origin rpy="0 1.5 0" xyz="-0.1 0.1 0"/>
        <material name="black"/>
      </visual>
    </link>
    <link name="wheel_3">
      <visual>
        <geometry>
          <cylinder length="0.05" radius="0.05"/>
        </geometry>
        <origin rpy="0 1.5 0" xyz="0.1 -0.1 0"/>
        <material name="black"/>
      </visual>
    </link>

    <link name="wheel_4">
      <visual>
        <geometry>
          <cylinder length="0.05" radius="0.05"/>
        </geometry>
        <origin rpy="0 1.5 0" xyz="-0.1 -0.1 0"/>
        <material name="black"/>
      </visual>
    </link>

    <joint name="base_to_wheel1" type="continuous">
      <parent link="base_link"/>
      <child link="wheel_1"/>
      <origin xyz="0 0 0"/>
    </joint>

    <joint name="base_to_wheel2" type="continuous">
      <parent link="base_link"/>
      <child link="wheel_2"/>
      <origin xyz="0 0 0"/>
    </joint>

    <joint name="base_to_wheel3" type="continuous">
      <parent link="base_link"/>
      <child link="wheel_3"/>
      <origin xyz="0 0 0"/>
    </joint>

    <joint name="base_to_wheel4" type="continuous">
      <parent link="base_link"/>
      <child link="wheel_4"/>
      <origin xyz="0 0 0"/>
    </joint>
  </robot>
