<?xml version="1.0"?>
  <robot name="smr">
    <link name="base_link">
      <visual>
        <geometry>
          <box size="0.30 .30 .15"/>
        </geometry>
        <origin rpy="0 0 0" xyz="0.15 0 0.15"/>
	<material name="gray">
        	<color rgba="0.5 0.5 0.5 1"/>
        </material>
      </visual>
    </link>

    <link name="base_scan">
      <visual>
        <geometry>
          <box size="0.08 .08 .1"/>
        </geometry>
        <origin rpy="0 0 0" xyz="0.08 0 0.02"/>
	<material name="gray">
        	<color rgba="0.5 0.5 0.5 1"/>
        </material>
      </visual>
    </link>

    <joint name="base_to_scan" type="fixed">
    	<parent link="base_link"/>
    	<child link="base_scan"/>
    	<origin xyz="0.25 0 0.05"/>
    </joint>

    <link name="laser">
      <visual>
        <geometry>
          <box size="0 0 0"/>
        </geometry>
        <origin rpy="0 0 0" xyz="0 0 0"/>
	<material name="gray">
        	<color rgba="0.5 0.5 0.5 1"/>
        </material>
      </visual>
    </link>

    <joint name="scan_to_laser" type="fixed">
    	<parent link="base_scan"/>
    	<child link="laser"/>
    	<origin rpy="3.14 0 0" xyz="0 0 0"/>
    </joint>


    <link name="wheel_BR">
      <visual>
        <geometry>
          <cylinder length="0.05" radius="0.05"/>
        </geometry>
        <origin rpy="1.57 0 0" xyz="0 0 0"/>
        <material name="black"/>
      </visual>
    </link>

    <joint name="base_to_wheelBR" type="continuous">
      <parent link="base_link"/>
      <child link="wheel_BR"/>
      <origin xyz="0.05 -0.125 0.05"/>
    </joint>

    <link name="wheel_BL">
      <visual>
        <geometry>
          <cylinder length="0.05" radius="0.05"/>
        </geometry>
        <origin rpy="1.57 0 0" xyz="0 0 0"/>
        <material name="black"/>
      </visual>
    </link>

    <joint name="base_to_wheelBL" type="continuous">
      <parent link="base_link"/>
      <child link="wheel_BL"/>
      <origin xyz="0.05 0.125 0.05"/>
    </joint>

    <link name="wheel_FR">
      <visual>
        <geometry>
          <cylinder length="0.05" radius="0.05"/>
        </geometry>
        <origin rpy="1.57 0 0" xyz="0 0 0"/>
        <material name="black"/>
      </visual>
    </link>

    <joint name="base_to_wheelFR" type="continuous">
      <parent link="base_link"/>
      <child link="wheel_FR"/>
      <origin xyz="0.25 -0.125 0.05"/>
    </joint>

    <link name="wheel_FL">
      <visual>
        <geometry>
          <cylinder length="0.05" radius="0.05"/>
        </geometry>
        <origin rpy="1.57 0 0" xyz="0 0 0"/>
        <material name="black"/>
      </visual>
    </link>

    <joint name="base_to_wheelFL" type="continuous">
      <parent link="base_link"/>
      <child link="wheel_FL"/>
      <origin xyz="0.25 0.125 0.05"/>
    </joint>

    <link name="kinect_support">
      <visual>
        <geometry>
          <box size="0.03 0.03 0.90"/>
        </geometry>
        <origin rpy="0 0 0" xyz="0 0 0.45"/>
        <material name="gray"/>
      </visual>
    </link>

    <joint name="base_to_support" type="fixed">
      <parent link="base_link"/>
      <child link="kinect_support"/>
      <origin xyz="-0.015 0 0.075"/>
    </joint>

   <link name="camera_link">
  <visual>
    <geometry>
      <box size="0.064 0.121 0.0381" />
    </geometry>
    <origin rpy="0 0 0" xyz="0 0 0"/>
    <material name="Blue" />
  </visual>
  <inertial>
      <mass value="0.0001" />
      <origin xyz="0 0 0" />
      <inertia ixx="0.0001" ixy="0.0" ixz="0.0"
               iyy="0.0001" iyz="0.0" 
               izz="0.0001" />
  </inertial>
</link>

<joint name="support_to_kinect" type="fixed">
      <parent link="kinect_support"/>
      <child link="camera_link"/>
      <origin rpy="0 -0.06 0" xyz="0 0 0.89"/>
    </joint>

<link name="kinect_depth_frame">
  <inertial>
      <mass value="0.0001" />
      <origin xyz="0 0 0" />
      <inertia ixx="0.0001" ixy="0.0" ixz="0.0"
               iyy="0.0001" iyz="0.0" 
               izz="0.0001" />
  </inertial>
</link>

<joint name="kinect_depth_joint" type="fixed">
  <origin xyz="0 0.028 0" rpy="0 0 0" />
  <parent link="camera_link" />
  <child link="kinect_depth_frame" />
</joint>


<link name="kinect_depth_optical_frame">
  <inertial>
      <mass value="0.0001" />
      <origin xyz="0 0 0" />
      <inertia ixx="0.0001" ixy="0.0" ixz="0.0"
               iyy="0.0001" iyz="0.0" 
               izz="0.0001" />
  </inertial>
</link>

<joint name="depth_optical_joint" type="fixed">
  <origin xyz="0 0 0" rpy="1.57 0 1.57" />
  <parent link="kinect_depth_frame" />
  <child link="kinect_depth_optical_frame" />
</joint>

<link name="door_handles">
</link>

<joint name="door_handles_joint" type="fixed">
  <origin xyz="0 0 0" rpy="0 0 3.14" />
  <parent link="kinect_depth_optical_frame" />
  <child link="door_handles" />
</joint>

<link name="remote_link">
</link>

<joint name="remote_joint" type="fixed">
  <origin xyz="0 0 0" rpy="0 0 0" />
  <parent link="camera_link" />
  <child link="remote_link" />
</joint>
   
    
  </robot>
